Workbook

Sheet Source Ledger
A1: Yanou & Partners IT Services - Fixed Asset Ledger
A2: Accounting extract | As of 2026-08-09
A4: Ledger Asset ID | B4: Asset Tag | C4: Serial Number | D4: Capitalized | E4: Acquisition Cost | F4: Accumulated Depreciation | G4: Net Book Value | H4: Ledger Status | I4: As-of Date
A5: FA-000001 | B5: MD-00001 | C5: MD-LA-050001 | D5: No | E5: 1895 | F5: 1895 | G5: =E5-F5 | H5: Active | I5: 46243.5
A6: FA-000002 | B6: MD-00002 | C6: MD-MO-050002 | D6: No | E6: 610 | F6: 296.94 | G6: =E6-F6 | H6: Active | I6: 46243.5
A7: FA-000003 | B7: MD-00003 | C7: MD-MO-050003 | D7: No | E7: 1085 | F7: 487.17 | G7: =E7-F7 | H7: Active | I7: 46243.5
A8: FA-000004 | B8: MD-00004 | C8: MD-NE-050004 | D8: Yes | E8: 6380 | F8: 5439.38 | G8: =E8-F8 | H8: Active | I8: 46243.5
A9: FA-000005 | B9: MD-00005 | C9: MD-LA-050005 | D9: No | E9: 2075 | F9: 2075 | G9: =E9-F9 | H9: Active | I9: 46243.5
A10: FA-000006 | B10: MD-00006 | C10: MD-MO-050006 | D10: No | E10: 790 | F10: 330.06 | G10: =E10-F10 | H10: Active | I10: 46243.5
A11: FA-000007 | B11: MD-00007 | C11: MD-MO-050007 | D11: No | E11: 950 | F11: 317.32 | G11: =E11-F11 | H11: Active | I11: 46243.5
A12: FA-000008 | B12: MD-00008 | C12: MD-NE-050008 | D12: Yes | E12: 6245 | F12: 4889.99 | G12: =E12-F12 | H12: Active | I12: 46243.5
A13: FA-000009 | B13: MD-00009 | C13: MD-LA-050009 | D13: No | E13: 1940 | F13: 1830.67 | G13: =E13-F13 | H13: Active | I13: 46243.5
A14: FA-000010 | B14: MD-00010 | C14: MD-MO-050010 | D14: No | E14: 655 | F14: 228.11 | G14: =E14-F14 | H14: Active | I14: 46243.5
A15: FA-000011 | B15: MD-00011 | C15: MD-MO-050011 | D15: No | E15: 1130 | F15: 247.5 | G15: =E15-F15 | H15: Active | I15: 46243.5
A16: FA-000012 | B16: MD-00012 | C16: MD-NE-050012 | D16: Yes | E16: 6425 | F16: 5871.77 | G16: =E16-F16 | H16: Active | I16: 46243.5
... A20: FA-000016 | B20: MD-00016 | C20: MD-NE-050016 | D20: Yes | E20: 6290 | F20: 5321.31 | G20: =E20-F20 | H20: Active | I20: 46243.5
A21: FA-000017 | B21: MD-00017 | C21: MD-LA-050017 | D21: No | E21: 2070 | F21: 2160 | G21: 0 | H21: Active | I21: 46243.5
A22: FA-000018 | B22: MD-00018 | C22: MD-MO-050018 | D22: No | E22: 700 | F22: 287.86 | G22: =E22-F22 | H22: Active | I22: 46243.5
A23: FA-000019 | B23: MD-00019 | C23: MD-MO-050019 | D23: No | E23: 1175 | F23: 379.6 | G23: =E23-F23 | H23: Active | I23: 46243.5
A24: FA-000020 | B24: MD-00020 | C24: MD-NE-050020 | D24: Yes | E24: 6470 | F24: 5023.66 | G24: =E24-F24 | H24: Active | I24: 46243.5
A25: FA-000021 | B25: MD-00021 | C25: MD-LA-050021 | D25: No | E25: 1850 | F25: 1725.48 | G25: =E25-F25 | H25: Active | I25: 46243.5
A26: FA-000022 | B26: MD-00022 | C26: MD-MO-050022 | D26: No | E26: 565 | F26: 193.05 | G26: =E26-F26 | H26: Active | I26: 46243.5
A27: FA-000023 | B27: MD-00023 | C27: MD-MO-050023 | D27: No | E27: 1040 | F27: 216.4 | G27: =E27-F27 | H27: Active | I27: 46243.5
A28: FA-000024 | B28: MD-00024 | C28: MD-NE-050024 | D28: Yes | E28: 6335 | F28: 5831.15 | G28: =E28-F28 | H28: Active | I28: 46243.5
A29: FA-000025 | B29: MD-00025 | C29: MD-LA-050021 | D29: No | E29: 2030 | F29: 2030 | G29: =E29-F29 | H29: Active | I29: 46243.5
A30: FA-000026 | B30: MD-00026 | C30: MD-MO-050026 | D30: No | E30: 745 | F30: 362.66 | G30: =E30-F30 | H30: Active | I30: 46243.5
A31: FA-000027 | B31: MD-00027 | C31: MD-MO-050027 | D31: No | E31: 1220 | F31: 547.79 | G31: =E31-F31 | H31: Active | I31: 46243.5
A32: FA-000028 | B32: MD-00028 | C32: MD-NE-050028 | D32: Yes | E32: 6200 | F32: 5285.91 | G32: =E32-F32 | H32: Active | I32: 46243.5
A33: FA-000029 | B33: MD-00029 | C33: MD-LA-050029 | D33: No | E33: 1895 | F33: 1895 | G33: =E33-F33 | H33: Active | I33: 46243.5
... A54: FA-000050 | B54: MD-00050 | C54: MD-MO-050050 | D54: No | E54: 565 | F54: 275.04 | G54: =E54-F54 | H54: Active | I54: 46243.5
A55: FA-000051 | B55: MD-00051 | C55: MD-MO-050051 | D55: No | E55: 1250 | F55: 641.97 | G55: 573.03 | H55: Active | I55: 46243.5
A56: FA-000052 | B56: MD-00052 | C56: MD-NE-050052 | D56: Yes | E56: 6335 | F56: 5401.01 | G56: =E56-F56 | H56: Active | I56: 46243.5
A57: FA-000053 | B57: MD-00053 | C57: MD-LA-050053 | D57: No | E57: 2030 | F57: 2030 | G57: =E57-F57 | H57: Active | I57: 46243.5
A58: FA-000054 | B58: MD-00054 | C58: MD-MO-050054 | D58: No | E58: 745 | F58: 311.26 | G58: =E58-F58 | H58: Active | I58: 46243.5
A59: FA-000055 | B59: MD-00055 | C59: MD-MO-050055 | D59: No | E59: 1220 | F59: 407.5 | G59: =E59-F59 | H59: Active | I59: 46243.5
A60: FA-000056 | B60: MD-00056 | C60: MD-NE-050056 | D60: Yes | E60: 6200 | F60: 4854.76 | G60: =E60-F60 | H60: Active | I60: 46243.5
A61: FA-000057 | B61: MD-00057 | C61: MD-LA-050057 | D61: No | E61: 1895 | F61: 1788.21 | G61: =E61-F61 | H61: Active | I61: 46243.5
A62: FA-000058 | B62: MD-00058 | C62: MD-MO-050058 | D62: No | E62: 610 | F62: 212.44 | G62: =E62-F62 | H62: Active | I62: 46243.5
A63: FA-000059 | B63: MD-00059 | C63: MD-MO-050059 | D63: No | E63: 1085 | F63: 237.65 | G63: =E63-F63 | H63: Active | I63: 46243.5
A64: FA-000060 | B64: MD-00060 | C64: MD-NE-050060 | D64: Yes | E64: 6380 | F64: 5830.65 | G64: =E64-F64 | H64: Active | I64: 46243.5
...

Sheet Source Inventory
A1: Source Inventory (from it_asset_inventory.xlsx)
A2: Operational snapshot used by Corrected Register lookups.
A4: Asset Tag | B4: Serial Number | C4: Category | D4: Model | E4: Assigned Employee | F4: Location | G4: Lifecycle Status | H4: Acquisition Cost
A5: MD-00001 | B5: MD-LA-050001 | C5: Laptop | D5: HP EliteBook 840 G10 | E5: E0001 | F5: Chicago | G5: In Use | H5: 1895
A6: MD-00002 | B6: MD-MO-050002 | C6: Laptop | D6: Microsoft Surface Laptop 5 | E6: E0002 | F6: Dallas | G6: In Use | H6: 610
A7: MD-00003 | B7: MD-MO-050003 | C7: Laptop | D7: Lenovo ThinkPad X1 Carbon | E7: E0003 | F7: Denver | G7: In Use | H7: 1085
A8: MD-00004 | B8: MD-NE-050004 | C8: Laptop | D8: Lenovo ThinkPad T14 | E8: E0004 | F8: New York | G8: In Use | H8: 6380
A9: MD-00005 | B9: MD-LA-050005 | C9: Laptop | D9: MacBook Pro 14 | E9: E0005 | F9: Seattle | G9: In Use | H9: 2075
A10: MD-00006 | B10: MD-MO-050006 | C10: Laptop | D10: Dell Latitude 7440 | E10: E0006 | F10: Atlanta | G10: In Use | H10: 790
A11: MD-00007 | B11: MD-MO-050007 | C11: Laptop | D11: HP EliteBook 840 G10 | E11: E0007 | F11: Chicago | G11: In Use | H11: 950
A12: MD-00008 | B12: MD-NE-050008 | C12: Monitor | D12: Samsung ViewFinity S8 | E12: E0008 | F12: Dallas | G12: In Use | H12: 6245
A13: MD-00009 | B13: MD-LA-050009 | C13: Monitor | D13: BenQ PD2705U | E13: E0009 | F13: Denver | G13: In Use | H13: 1940
A14: MD-00010 | B14: MD-MO-050010 | C14: Monitor | D14: Dell U2723QE | E14: E0010 | F14: New York | G14: In Use | H14: 655
A15: MD-00011 | B15: MD-MO-050011 | C15: Monitor | D15: LG UltraFine 27MD5KL | E15: E0011 | F15: Seattle | G15: In Use | H15: 1130
A16: MD-00012 | B16: MD-NE-050012 | C16: Monitor | D16: Samsung ViewFinity S8 | E16: E0012 | F16: Atlanta | G16: In Use | H16: 6425
... A49: MD-00045 | B49: MD-LA-050045 | C49: Mobile Device | D49: Samsung Galaxy S23 FE | E49: E0045 | F49: Denver - Closed | G49: In Use | H49: 1985
A50: MD-00046 | B50: MD-MO-050046 | C50: Mobile Device | D50: iPhone 14 | F50: Chicago - Closed | G50: Available | H50: 700
A51: MD-00047 | B51: MD-MO-050047 | C51: Mobile Device | D51: Samsung Galaxy S24 | F51: Denver - Closed | G51: Available | H51: 1175
A52: MD-00048 | B52: MD-NE-050048 | C52: Mobile Device | D52: iPhone 15 | F52: Chicago - Closed | G52: Available | H52: 6470
A53: MD-00049 | B53: MD-LA-050049 | C53: Mobile Device | D53: Google Pixel 8 | F53: Denver - Closed | G53: Available | H53: 1850
A54: MD-00050 | B54: MD-MO-050050 | C54: Mobile Device | D54: iPhone 14 | F54: Chicago - Closed | G54: Available | H54: 565
A55: MD-00051 | B55: MD-MO-050051 | C55: Mobile Device | D55: Samsung Galaxy S24 | F55: Denver - Closed | G55: Available | H55: 1040
A56: MD-00052 | B56: MD-NE-050052 | C56: Mobile Device | D56: iPhone 15 | F56: Chicago - Closed | G56: Available | H56: 6335
A57: MD-00053 | B57: MD-LA-050053 | C57: Mobile Device | D57: Google Pixel 8 | F57: Denver - Closed | G57: Available | H57: 2030
A58: MD-00054 | B58: MD-MO-050054 | C58: Mobile Device | D58: Samsung Galaxy S23 FE | F58: Chicago - Closed | G58: Available | H58: 745
A59: MD-00055 | B59: MD-MO-050055 | C59: Mobile Device | D59: iPhone 14 | F59: Denver - Closed | G59: Available | H59: 1220
A60: MD-00056 | B60: MD-NE-050056 | C60: Mobile Device | D60: Samsung Galaxy S24 | F60: Chicago - Closed | G60: Available | H60: 6200
A61: MD-00057 | B61: MD-LA-050057 | C61: Mobile Device | D61: iPhone 15 | F61: Denver - Closed | G61: Available | H61: 1895
A62: MD-00058 | B62: MD-MO-050058 | C62: Mobile Device | D62: Google Pixel 8 | E62: E0071 | F62: Chicago - Closed | G62: Assigned | H62: 610
A63: MD-00059 | B63: MD-MO-050059 | C63: Mobile Device | D63: Samsung Galaxy S23 FE | E63: E0072 | F63: Denver - Closed | G63: Assigned | H63: 1085
A64: MD-00060 | B64: MD-NE-050060 | C64: Mobile Device | D64: Samsung Galaxy S24 | E64: E0073 | F64: Chicago - Closed | G64: Assigned | H64: 6380
A65: MD-00061 | B65: MD-LA-050061 | C65: Mobile Device | D65: iPhone 15 | E65: E0074 | F65: Denver - Closed | G65: Assigned | H65: 2075
A66: MD-00062 | B66: MD-MO-050062 | C66: Mobile Device | D66: Google Pixel 8 | E66: E0075 | F66: Chicago - Closed | G66: Assigned | H66: 790
A67: MD-00063 | B67: MD-MO-050063 | C67: Mobile Device | D67: Samsung Galaxy S23 FE | E67: E0076 | F67: Denver - Closed | G67: Assigned | H67: 950
A68: MD-00064 | B68: MD-NE-050064 | C68: Mobile Device | D68: iPhone 14 | E68: E0077 | F68: Chicago - Closed | G68: Assigned | H68: 6245
A69: MD-00065 | B69: MD-LA-050065 | C69: Mobile Device | D69: Samsung Galaxy S24 | E69: E0078 | F69: Denver - Closed | G69: Assigned | H69: 1940
A70: MD-00066 | B70: MD-MO-050066 | C70: Mobile Device | D70: iPhone 15 | E70: E0079 | F70: Chicago - Closed | G70: Assigned | H70: 655
A71: MD-00067 | B71: MD-MO-050067 | C71: Mobile Device | D71: Google Pixel 8 | E71: E0080 | F71: Denver - Closed | G71: Assigned | H71: 1130
A72: MD-00068 | B72: MD-NE-050068 | C72: Mobile Device | D72: Samsung Galaxy S23 FE | E72: E0081 | F72: Chicago - Closed | G72: Assigned | H72: 6425
A73: MD-00069 | B73: MD-LA-050069 | C73: Mobile Device | D73: iPhone 14 | E73: E0082 | F73: Denver - Closed | G73: Assigned | H73: 2120
...

Sheet Dashboard
A1: Yanou & Partners IT Services - IT Asset Reconciliation Dashboard
A2: Prepared for IT Operations Manager, Finance Controller, HR Operations Lead, and Internal Audit | As of 2026-08-09 | Policy figure and dock image used as leads only
A4: KPI | B4: Value
A5: Assets reviewed | B5: 132
A6: Corrected register acquisition cost | B6: 332115
A7: Remaining book value (ledger NBV where present) | B7: 61526.6
A8: Open exceptions | B8: 163
A9: Certification blockers (Critical impact) | B9: 43
A10: Assets Missing / Cannot Locate | B10: 12
A11: Overdue returns (label ≠ proof) | B11: 12
A12: Verified disposed with certificate | B12: 8
A13: Custody chains documented | B13: 65
A14: Multimodal image leads cited | B14: ITAM_control_matrix.png; receiving_exception_scan_1ZMD00000082.png
A17: Asset Counts and Book Value by Verified Status | E17: By Device Category
A18: Verified Status | B18: Asset Count | C18: Book Value | E18: Category | F18: Asset Count | G18: Book Value
A19: Available | B19: 25 | C19: 12961 | E19: Laptop | F19: 40 | G19: 13030.88
A20: Disposed | B20: 8 | C20: 0 | E20: Mobile Device | F20: 36 | G20: 18983.58
A21: In Transit - Exception | B21: 2 | C21: 1019.4 | E21: Monitor | F21: 28 | G21: 15372.27
A22: In Use | B22: 51 | C22: 25477.76 | E22: Network Asset | F22: 28 | G22: 14139.87
A23: Missing | B23: 12 | C23: 6214.38
A24: Pending Redeployment | B24: 10 | C24: 4851.08
A25: Retired/Pending Disposal | B25: 12 | C25: 4811.33
A26: Return Overdue | B26: 12 | C26: 6191.65
A30: By Verified Location | E30: Open Exceptions by Type
A31: Verified Location | B31: Asset Count | C31: Book Value | E31: Type | F31: Count | G31: Financial Exposure
A32: Chicago | B32: 16 | C32: 5184.18 | E32: Cannot Locate | F32: 12 | G32: 6214.38
A33: Atlanta | B33: 15 | C33: 6267.29 | E33: Closed Location Assignment | F33: 61 | G33: 29063.84
A34: Dallas | B34: 15 | C34: 11070.95 | E34: Duplicate Serial Number | F34: 4 | G34: 2503.11
A35: Seattle | B35: 15 | C35: 5149.95 | E35: Former Employee Assignment | F35: 43 | G35: 22627.56
A36: Denver | B36: 14 | C36: 5551.75 | E36: Inventory-to-Ledger Difference | F36: 8 | G36: 7275
A37: New York | B37: 14 | C37: 10526 | E37: Missing Disposal Evidence | F37: 12 | G37: 4811.33
A38: Unknown | B38: 12 | C38: 6214.38 | E38: Overdue Return | F38: 12 | G38: 6191.65
A39: Remote - Former Employee | B39: 10 | C39: 4878.51 | E39: Shipment Mismatch | F39: 4 | G39: 2332.54
A40: Disposed | B40: 8 | C40: 0 | E40: Unapproved Transfer | F40: 5 | G40: 2869.32
A41: Atlanta Warehouse | B41: 7 | C41: 4351.05 | E41: Below Capitalization Threshold | F41: 2 | G41: 0
A42: Carrier Network / Unverified | B42: 4 | C42: 2332.54
A43: Disposed (certificate missing) | B43: 2 | C43: 0
A45: Key finding - Duplicate serial identities (both pairs)
A46: Duplicate Serial | B46: Asset Tags Sharing This Serial | C46: Exception IDs
A47: MD-LA-050021 | B47: MD-00021 and MD-00025 | C47: EX-0002; EX-0004
...

Sheet Corrected Register
A1: Corrected Asset Register
A2: Every reviewed asset with verified custodian, location, status, evidence (including multimodal leads where applicable), cost, book value, and confidence. As of 2026-08-09.
A4: Asset Tag | B4: Serial Number | C4: Category | D4: Model | E4: Register Custodian | F4: Register Location | G4: Register Status | H4: Verified Custodian | I4: Verified Location | J4: Verified Status | K4: Evidence Source | L4: Last Verified Date | M4: Acquisition Cost | N4: Remaining Book Value | O4: Ledger Asset ID | P4: Capitalized | Q4: Confidence | R4: Exception IDs | S4: Escalation Required | T4: Ledger Acquisition Cost | U4: Ledger Status | V4: FA Net Book Value | W4: Ledger vs Register Cost Diff | X4: Book Value Present
A5: MD-00001 | B5: =IFERROR(XLOOKUP(A5,'Source Inventory'!$A$5:$A$200,'Source Inventory'!$B$5:$B$200),"") | C5: =IFERROR(XLOOKUP(A5,'Source Inventory'!$A$5:$A$200,'Source Inventory'!$C$5:$C$200),"") | D5: =IFERROR(XLOOKUP(A5,'Source Inventory'!$A$5:$A$200,'Source Inventory'!$D$5:$D$200),"") | E5: =IFERROR(XLOOKUP(A5,'Source Inventory'!$A$5:$A$200,'Source Inventory'!$E$5:$E$200),"") | F5: =IFERROR(XLOOKUP(A5,'Source Inventory'!$A$5:$A$200,'Source Inventory'!$F$5:$F$200),"") | G5: =IFERROR(XLOOKUP(A5,'Source Inventory'!$A$5:$A$200,'Source Inventory'!$G$5:$G$200),"") | H5: E0001 | I5: Chicago | J5: In Use | K5: Files reviewed for MD-00001: HP EliteBook 840 G10, basis $1895, operating site Chicago, status In Use. Source Ledger FA-000001; net book value $0. equipment_transfer_log TR-00001 posted Jan 21, 2026; inbound 2026-01-21 approval APR-00001. hr_employee_status lists Priya Shah (E0001) as Active. hardware_purchase_orders.csv ties MD-00001 to PO-2022-0001. | L5: 2026-08-05 | M5: =IFERROR(XLOOKUP(A5,'Source Inventory'!$A$5:$A$200,'Source Inventory'!$H$5:$H$200),"") | N5: 0 | O5: =IFERROR(XLOOKUP(A5,'Source Ledger'!$B$5:$B$200,'Source Ledger'!$A$5:$A$200),"") | P5: =IFERROR(XLOOKUP(A5,'Source Ledger'!$B$5:$B$200,'Source Ledger'!$D$5:$D$200),"") | Q5: High | S5: =IF(OR(R5="",R5=0),"No","Yes") | T5: =IFERROR(XLOOKUP(A5,'Source Ledger'!$B$5:$B$200,'Source Ledger'!$E$5:$E$200),"") | U5: =IFERROR(XLOOKUP(A5,'Source Ledger'!$B$5:$B$200,'Source Ledger'!$H$5:$H$200),"") | V5: =IFERROR(XLOOKUP(A5,'Source Ledger'!$B$5:$B$200,'Source Ledger'!$G$5:$G$200),"") | W5: =IF(OR(M5="",T5=""),"",T5-M5) | X5: =IF(V5="","No","Yes")
A6: MD-00002 | B6: =IFERROR(XLOOKUP(A6,'Source Inventory'!$A$5:$A$200,'Source Inventory'!$B$5:$B$200),"") | C6: =IFERROR(XLOOKUP(A6,'Source Inventory'!$A$5:$A$200,'Source Inventory'!$C$5:$C$200),"") | D6: =IFERROR(XLOOKUP(A6,'Source Inventory'!$A$5:$A$200,'Source Inventory'!$D$5:$D$200),"") | E6: =IFERROR(XLOOKUP(A6,'Source Inventory'!$A$5:$A$200,'Source Inventory'!$E$5:$E$200),"") | F6: =IFERROR(XLOOKUP(A6,'Source Inventory'!$A$5:$A$200,'Source Inventory'!$F$5:$F$200),"") | G6: =IFERROR(XLOOKUP(A6,'Source Inventory'!$A$5:$A$200,'Source Inventory'!$G$5:$G$200),"") | H6: E0002 | I6: Dallas | J6: In Use | K6: Cross-checked MD-00002 (MD-MO-050002, Microsoft Surface Laptop 5) against HR, transfers, and ledger extracts. Source Ledger FA-000002; net book value $313.06. equipment_transfer_log TR-00002 posted Feb 23, 2026; inbound 2026-02-25 approval APR-00002. hr_employee_status lists Marcus Ellison (E0002) as Active. capital PO PO-2022-0001 supports the cost basis. | L6: 2026-08-05 | M6: =IFERROR(XLOOKUP(A6,'Source Inventory'!$A$5:$A$200,'Source Inventory'!$H$5:$H$200),"") | N6: 313.06 | O6: =IFERROR(XLOOKUP(A6,'Source Ledger'!$B$5:$B$200,'Source Ledger'!$A$5:$A$200),"") | P6: =IFERROR(XLOOKUP(A6,'Source Ledger'!$B$5:$B$200,'Source Ledger'!$D$5:$D$200),"") | Q6: High | S6: =IF(OR(R6="",R6=0),"No","Yes") | T6: =IFERROR(XLOOKUP(A6,'Source Ledger'!$B$5:$B$200,'Source Ledger'!$E$5:$E$200),"") | U6: =IFERROR(XLOOKUP(A6,'Source Ledger'!$B$5:$B$200,'Source Ledger'!$H$5:$H$200),"") | V6: =IFERROR(XLOOKUP(A6,'Source Ledger'!$B$5:$B$200,'Source Ledger'!$G$5:$G$200),"") | W6: =IF(OR(M6="",T6=""),"",T6-M6) | X6: =IF(V6="","No","Yes")
A7: MD-00003 | B7: =IFERROR(XLOOKUP(A7,'Source Inventory'!$A$5:$A$200,'Source Inventory'!$B$5:$B$200),"") | C7: =IFERROR(XLOOKUP(A7,'Source Inventory'!$A$5:$A$200,'Source Inventory'!$C$5:$C$200),"") | D7: =IFERROR(XLOOKUP(A7,'Source Inventory'!$A$5:$A$200,'Source Inventory'!$D$5:$D$200),"") | E7: =IFERROR(XLOOKUP(A7,'Source Inventory'!$A$5:$A$200,'Source Inventory'!$E$5:$E$200),"") | F7: =IFERROR(XLOOKUP(A7,'Source Inventory'!$A$5:$A$200,'Source Inventory'!$F$5:$F$200),"") | G7: =IFERROR(XLOOKUP(A7,'Source Inventory'!$A$5:$A$200,'Source Inventory'!$G$5:$G$200),"") | H7: E0003 | I7: Denver | J7: In Use | K7: Cross-checked MD-00003 (MD-MO-050003, Lenovo ThinkPad X1 Carbon) against HR, transfers, and ledger extracts. Source Ledger FA-000003; net book value $597.83. equipment_transfer_log TR-00003 posted Mar 31, 2026; inbound 2026-04-03 approval APR-00003. hr_employee_status lists Elena Kovacs (E0003) as Active. hardware_purchase_orders.csv ties MD-00003 to PO-2022-0001. | L7: 2026-08-05 | M7: =IFERROR(XLOOKUP(A7,'Source Inventory'!$A$5:$A$200,'Source Inventory'!$H$5:$H$200),"") | N7: 597.83 | O7: =IFERROR(XLOOKUP(A7,'Source Ledger'!$B$5:$B$200,'Source Ledger'!$A$5:$A$200),"") | P7: =IFERROR(XLOOKUP(A7,'Source Ledger'!$B$5:$B$200,'Source Ledger'!$D$5:$D$200),"") | Q7: High | S7: =IF(OR(R7="",R7=0),"No","Yes") | T7: =IFERROR(XLOOKUP(A7,'Source Ledger'!$B$5:$B$200,'Source Ledger'!$E$5:$E$200),"") | U7: =IFERROR(XLOOKUP(A7,'Source Ledger'!$B$5:$B$200,'Source Ledger'!$H$5:$H$200),"") | V7: =IFERROR(XLOOKUP(A7,'Source Ledger'!$B$5:$B$200,'Source Ledger'!$G$5:$G$200),"") | W7: =IF(OR(M7="",T7=""),"",T7-M7) | X7: =IF(V7="","No","Yes")
A8: MD-00004 | B8: =IFERROR(XLOOKUP(A8,'Source Inventory'!$A$5:$A$200,'Source Inventory'!$B$5:$B$200),"") | C8: =IFERROR(XLOOKUP(A8,'Source Inventory'!$A$5:$A$200,'Source Inventory'!$C$5:$C$200),"") | D8: =IFERROR(XLOOKUP(A8,'Source Inventory'!$A$5:$A$200,'Source Inventory'!$D$5:$D$200),"") | E8: =IFERROR(XLOOKUP(A8,'Source Inventory'!$A$5:$A$200,'Source Inventory'!$E$5:$E$200),"") | F8: =IFERROR(XLOOKUP(A8,'Source Inventory'!$A$5:$A$200,'Source Inventory'!$F$5:$F$200),"") | G8: =IFERROR(XLOOKUP(A8,'Source Inventory'!$A$5:$A$200,'Source Inventory'!$G$5:$G$200),"") | H8: E0004 | I8: New York | J8: In Use | K8: Cross-checked MD-00004 (MD-NE-050004, Lenovo ThinkPad T14) against HR, transfers, and ledger extracts. Source Ledger FA-000004; net book value $940.62. equipment_transfer_log TR-00004 posted May 01, 2026; inbound 2026-05-01 approval APR-00004. hr_employee_status lists James Whitaker (E0004) as Active. hardware_purchase_orders.csv ties MD-00004 to PO-2023-0002. | L8: 2026-08-05 | M8: =IFERROR(XLOOKUP(A8,'Source Inventory'!$A$5:$A$200,'Source Inventory'!$H$5:$H$200),"") | N8: 940.62 | O8: =IFERROR(XLOOKUP(A8,'Source Ledger'!$B$5:$B$200,'Source Ledger'!$A$5:$A$200),"") | P8: =IFERROR(XLOOKUP(A8,'Source Ledger'!$B$5:$B$200,'Source Ledger'!$D$5:$D$200),"") | Q8: High | S8: =IF(OR(R8="",R8=0),"No","Yes") | T8: =IFERROR(XLOOKUP(A8,'Source Ledger'!$B$5:$B$200,'Source Ledger'!$E$5:$E$200),"") | U8: =IFERROR(XLOOKUP(A8,'Source Ledger'!$B$5:$B$200,'Source Ledger'!$H$5:$H$200),"") | V8: =IFERROR(XLOOKUP(A8,'Source Ledger'!$B$5:$B$200,'Source Ledger'!$G$5:$G$200),"") | W8: =IF(OR(M8="",T8=""),"",T8-M8) | X8: =IF(V8="","No","Yes")
A9: MD-00005 | B9: =IFERROR(XLOOKUP(A9,'Source Inventory'!$A$5:$A$200,'Source Inventory'!$B$5:$B$200),"") | C9: =IFERROR(XLOOKUP(A9,'Source Inventory'!$A$5:$A$200,'Source Inventory'!$C$5:$C$200),"") | D9: =IFERROR(XLOOKUP(A9,'Source Inventory'!$A$5:$A$200,'Source Inventory'!$D$5:$D$200),"") | E9: =IFERROR(XLOOKUP(A9,'Source Inventory'!$A$5:$A$200,'Source Inventory'!$E$5:$E$200),"") | F9: =IFERROR(XLOOKUP(A9,'Source Inventory'!$A$5:$A$200,'Source Inventory'!$F$5:$F$200),"") | G9: =IFERROR(XLOOKUP(A9,'Source Inventory'!$A$5:$A$200,'Source Inventory'!$G$5:$G$200),"") | H9: E0005 | I9: Seattle | J9: In Use | K9: Reconciliation packet cites MD-00005 with acquisition $2075 and custody In Use at Seattle. Source Ledger FA-000005; net book value $0. capital PO PO-2023-0002 supports the cost basis. equipment_transfer_log TR-00005 posted Jun 05, 2026; inbound 2026-06-08 approval APR-00005. hr_employee_status lists Aisha Rahman (E0005) as Active. | L9: 2026-08-05 | M9: =IFERROR(XLOOKUP(A9,'Source Inventory'!$A$5:$A$200,'Source Inventory'!$H$5:$H$200),"") | N9: 0 | O9: =IFERROR(XLOOKUP(A9,'Source Ledger'!$B$5:$B$200,'Source Ledger'!$A$5:$A$200),"") | P9: =IFERROR(XLOOKUP(A9,'Source Ledger'!$B$5:$B$200,'Source Ledger'!$D$5:$D$200),"") | Q9: High | S9: =IF(OR(R9="",R9=0),"No","Yes") | T9: =IFERROR(XLOOKUP(A9,'Source Ledger'!$B$5:$B$200,'Source Ledger'!$E$5:$E$200),"") | U9: =IFERROR(XLOOKUP(A9,'Source Ledger'!$B$5:$B$200,'Source Ledger'!$H$5:$H$200),"") | V9: =IFERROR(XLOOKUP(A9,'Source Ledger'!$B$5:$B$200,'Source Ledger'!$G$5:$G$200),"") | W9: =IF(OR(M9="",T9=""),"",T9-M9) | X9: =IF(V9="","No","Yes")
A10: MD-00006 | B10: =IFERROR(XLOOKUP(A10,'Source Inventory'!$A$5:$A$200,'Source Inventory'!$B$5:$B$200),"") | C10: =IFERROR(XLOOKUP(A10,'Source Inventory'!$A$5:$A$200,'Source Inventory'!$C$5:$C$200),"") | D10: =IFERROR(XLOOKUP(A10,'Source Inventory'!$A$5:$A$200,'Source Inventory'!$D$5:$D$200),"") | E10: =IFERROR(XLOOKUP(A10,'Source Inventory'!$A$5:$A$200,'Source Inventory'!$E$5:$E$200),"") | F10: =IFERROR(XLOOKUP(A10,'Source Inventory'!$A$5:$A$200,'Source Inventory'!$F$5:$F$200),"") | G10: =IFERROR(XLOOKUP(A10,'Source Inventory'!$A$5:$A$200,'Source Inventory'!$G$5:$G$200),"") | H10: E0006 | I10: Atlanta | J10: In Use | K10: Cross-checked MD-00006 (MD-MO-050006, Dell Latitude 7440) against HR, transfers, and ledger extracts. Source Ledger FA-000006; net book value $459.94. equipment_transfer_log TR-00006 posted Jan 10, 2026; inbound 2026-01-12 approval APR-00006. hr_employee_status lists Colin Bergstrom (E0006) as Active. order PO-2023-0002 appears in the purchasing extract. | L10: 2026-08-05 | M10: =IFERROR(XLOOKUP(A10,'Source Inventory'!$A$5:$A$200,'Source Inventory'!$H$5:$H$200),"") | N10: 459.94 | O10: =IFERROR(XLOOKUP(A10,'Source Ledger'!$B$5:$B$200,'Source Ledger'!$A$5:$A$200),"") | P10: =IFERROR(XLOOKUP(A10,'Source Ledger'!$B$5:$B$200,'Source Ledger'!$D$5:$D$200),"") | Q10: High | S10: =IF(OR(R10="",R10=0),"No","Yes") | T10: =IFERROR(XLOOKUP(A10,'Source Ledger'!$B$5:$B$200,'Source Ledger'!$E$5:$E$200),"") | U10: =IFERROR(XLOOKUP(A10,'Source Ledger'!$B$5:$B$200,'Source Ledger'!$H$5:$H$200),"") | V10: =IFERROR(XLOOKUP(A10,'Source Ledger'!$B$5:$B$200,'Source Ledger'!$G$5:$G$200),"") | W10: =IF(OR(M10="",T10=""),"",T10-M10) | X10: =IF(V10="","No","Yes")
A11: MD-00007 | B11: =IFERROR(XLOOKUP(A11,'Source Inventory'!$A$5:$A$200,'Source Inventory'!$B$5:$B$200),"") | C11: =IFERROR(XLOOKUP(A11,'Source Inventory'!$A$5:$A$200,'Source Inventory'!$C$5:$C$200),"") | D11: =IFERROR(XLOOKUP(A11,'Source Inventory'!$A$5:$A$200,'Source Inventory'!$D$5:$D$200),"") | E11: =IFERROR(XLOOKUP(A11,'Source Inventory'!$A$5:$A$200,'Source Inventory'!$E$5:$E$200),"") | F11: =IFERROR(XLOOKUP(A11,'Source Inventory'!$A$5:$A$200,'Source Inventory'!$F$5:$F$200),"") | G11: =IFERROR(XLOOKUP(A11,'Source Inventory'!$A$5:$A$200,'Source Inventory'!$G$5:$G$200),"") | H11: E0007 | I11: Chicago | J11: In Use | K11: Cross-checked MD-00007 (MD-MO-050007, HP EliteBook 840 G10) against HR, transfers, and ledger extracts. Source Ledger FA-000007; net book value $632.68. equipment_transfer_log TR-00007 posted Feb 11, 2026; inbound 2026-02-17 approval APR-00007. hr_employee_status lists Sofia Alvarez (E0007) as Active. PO-2023-0002 is the cited purchase order. | L11: 2026-08-05 | M11: =IFERROR(XLOOKUP(A11,'Source Inventory'!$A$5:$A$200,'Source Inventory'!$H$5:$H$200),"") | N11: 632.68 | O11: =IFERROR(XLOOKUP(A11,'Source Ledger'!$B$5:$B$200,'Source Ledger'!$A$5:$A$200),"") | P11: =IFERROR(XLOOKUP(A11,'Source Ledger'!$B$5:$B$200,'Source Ledger'!$D$5:$D$200),"") | Q11: High | S11: =IF(OR(R11="",R11=0),"No","Yes") | T11: =IFERROR(XLOOKUP(A11,'Source Ledger'!$B$5:$B$200,'Source Ledger'!$E$5:$E$200),"") | U11: =IFERROR(XLOOKUP(A11,'Source Ledger'!$B$5:$B$200,'Source Ledger'!$H$5:$H$200),"") | V11: =IFERROR(XLOOKUP(A11,'Source Ledger'!$B$5:$B$200,'Source Ledger'!$G$5:$G$200),"") | W11: =IF(OR(M11="",T11=""),"",T11-M11) | X11: =IF(V11="","No","Yes")
A12: MD-00008 | B12: =IFERROR(XLOOKUP(A12,'Source Inventory'!$A$5:$A$200,'Source Inventory'!$B$5:$B$200),"") | C12: =IFERROR(XLOOKUP(A12,'Source Inventory'!$A$5:$A$200,'Source Inventory'!$C$5:$C$200),"") | D12: =IFERROR(XLOOKUP(A12,'Source Inventory'!$A$5:$A$200,'Source Inventory'!$D$5:$D$200),"") | E12: =IFERROR(XLOOKUP(A12,'Source Inventory'!$A$5:$A$200,'Source Inventory'!$E$5:$E$200),"") | F12: =IFERROR(XLOOKUP(A12,'Source Inventory'!$A$5:$A$200,'Source Inventory'!$F$5:$F$200),"") | G12: =IFERROR(XLOOKUP(A12,'Source Inventory'!$A$5:$A$200,'Source Inventory'!$G$5:$G$200),"") | H12: E0008 | I12: Dallas | J12: In Use | K12: Cross-checked MD-00008 (MD-NE-050008, Samsung ViewFinity S8) against HR, transfers, and ledger extracts. Source Ledger FA-000008; net book value $1355.01. equipment_transfer_log TR-00008 posted Mar 16, 2026; inbound 2026-03-19 approval APR-00008. hr_employee_status lists Derek Nguyen (E0008) as Active. acquisition recorded on PO-2023-0002. | L12: 2026-08-05 | M12: =IFERROR(XLOOKUP(A12,'Source Inventory'!$A$5:$A$200,'Source Inventory'!$H$5:$H$200),"") | N12: 1355.01 | O12: =IFERROR(XLOOKUP(A12,'Source Ledger'!$B$5:$B$200,'Source Ledger'!$A$5:$A$200),"") | P12: =IFERROR(XLOOKUP(A12,'Source Ledger'!$B$5:$B$200,'Source Ledger'!$D$5:$D$200),"") | Q12: High | S12: =IF(OR(R12="",R12=0),"No","Yes") | T12: =IFERROR(XLOOKUP(A12,'Source Ledger'!$B$5:$B$200,'Source Ledger'!$E$5:$E$200),"") | U12: =IFERROR(XLOOKUP(A12,'Source Ledger'!$B$5:$B$200,'Source Ledger'!$H$5:$H$200),"") | V12: =IFERROR(XLOOKUP(A12,'Source Ledger'!$B$5:$B$200,'Source Ledger'!$G$5:$G$200),"") | W12: =IF(OR(M12="",T12=""),"",T12-M12) | X12: =IF(V12="","No","Yes")
A13: MD-00009 | B13: =IFERROR(XLOOKUP(A13,'Source Inventory'!$A$5:$A$200,'Source Inventory'!$B$5:$B$200),"") | C13: =IFERROR(XLOOKUP(A13,'Source Inventory'!$A$5:$A$200,'Source Inventory'!$C$5:$C$200),"") | D13: =IFERROR(XLOOKUP(A13,'Source Inventory'!$A$5:$A$200,'Source Inventory'!$D$5:$D$200),"") | E13: =IFERROR(XLOOKUP(A13,'Source Inventory'!$A$5:$A$200,'Source Inventory'!$E$5:$E$200),"") | F13: =IFERROR(XLOOKUP(A13,'Source Inventory'!$A$5:$A$200,'Source Inventory'!$F$5:$F$200),"") | G13: =IFERROR(XLOOKUP(A13,'Source Inventory'!$A$5:$A$200,'Source Inventory'!$G$5:$G$200),"") | H13: E0009 | I13: Denver | J13: In Use | K13: Working conclusion for MD-00009 (MD-LA-050009): In Use at Denver; cost $1940. equipment_transfer_log TR-00009 posted Apr 20, 2026; inbound 2026-04-21 approval APR-00009. hr_employee_status lists Hannah Cole (E0009) as Active. PO-2024-0003 is the cited purchase order. Source Ledger FA-000009; net book value $109.33. | L13: 2026-08-05 | M13: =IFERROR(XLOOKUP(A13,'Source Inventory'!$A$5:$A$200,'Source Inventory'!$H$5:$H$200),"") | N13: 109.33 | O13: =IFERROR(XLOOKUP(A13,'Source Ledger'!$B$5:$B$200,'Source Ledger'!$A$5:$A$200),"") | P13: =IFERROR(XLOOKUP(A13,'Source Ledger'!$B$5:$B$200,'Source Ledger'!$D$5:$D$200),"") | Q13: High | S13: =IF(OR(R13="",R13=0),"No","Yes") | T13: =IFERROR(XLOOKUP(A13,'Source Ledger'!$B$5:$B$200,'Source Ledger'!$E$5:$E$200),"") | U13: =IFERROR(XLOOKUP(A13,'Source Ledger'!$B$5:$B$200,'Source Ledger'!$H$5:$H$200),"") | V13: =IFERROR(XLOOKUP(A13,'Source Ledger'!$B$5:$B$200,'Source Ledger'!$G$5:$G$200),"") | W13: =IF(OR(M13="",T13=""),"",T13-M13) | X13: =IF(V13="","No","Yes")
A14: MD-00010 | B14: =IFERROR(XLOOKUP(A14,'Source Inventory'!$A$5:$A$200,'Source Inventory'!$B$5:$B$200),"") | C14: =IFERROR(XLOOKUP(A14,'Source Inventory'!$A$5:$A$200,'Source Inventory'!$C$5:$C$200),"") | D14: =IFERROR(XLOOKUP(A14,'Source Inventory'!$A$5:$A$200,'Source Inventory'!$D$5:$D$200),"") | E14: =IFERROR(XLOOKUP(A14,'Source Inventory'!$A$5:$A$200,'Source Inventory'!$E$5:$E$200),"") | F14: =IFERROR(XLOOKUP(A14,'Source Inventory'!$A$5:$A$200,'Source Inventory'!$F$5:$F$200),"") | G14: =IFERROR(XLOOKUP(A14,'Source Inventory'!$A$5:$A$200,'Source Inventory'!$G$5:$G$200),"") | H14: E0010 | I14: New York | J14: In Use | K14: Working conclusion for MD-00010 (MD-MO-050010): In Use at New York; cost $655. equipment_transfer_log TR-00010 posted May 22, 2026; inbound 2026-05-28 approval APR-00010. Source Ledger FA-000010; net book value $426.89. PO PO-2024-0003 documents the buy for MD-00010. hr_employee_status lists Owen Patel (E0010) as Active. | L14: 2026-08-05 | M14: =IFERROR(XLOOKUP(A14,'Source Inventory'!$A$5:$A$200,'Source Inventory'!$H$5:$H$200),"") | N14: 426.89 | O14: =IFERROR(XLOOKUP(A14,'Source Ledger'!$B$5:$B$200,'Source Ledger'!$A$5:$A$200),"") | P14: =IFERROR(XLOOKUP(A14,'Source Ledger'!$B$5:$B$200,'Source Ledger'!$D$5:$D$200),"") | Q14: High | S14: =IF(OR(R14="",R14=0),"No","Yes") | T14: =IFERROR(XLOOKUP(A14,'Source Ledger'!$B$5:$B$200,'Source Ledger'!$E$5:$E$200),"") | U14: =IFERROR(XLOOKUP(A14,'Source Ledger'!$B$5:$B$200,'Source Ledger'!$H$5:$H$200),"") | V14: =IFERROR(XLOOKUP(A14,'Source Ledger'!$B$5:$B$200,'Source Ledger'!$G$5:$G$200),"") | W14: =IF(OR(M14="",T14=""),"",T14-M14) | X14: =IF(V14="","No","Yes")
A15: MD-00011 | B15: =IFERROR(XLOOKUP(A15,'Source Inventory'!$A$5:$A$200,'Source Inventory'!$B$5:$B$200),"") | C15: =IFERROR(XLOOKUP(A15,'Source Inventory'!$A$5:$A$200,'Source Inventory'!$C$5:$C$200),"") | D15: =IFERROR(XLOOKUP(A15,'Source Inventory'!$A$5:$A$200,'Source Inventory'!$D$5:$D$200),"") | E15: =IFERROR(XLOOKUP(A15,'Source Inventory'!$A$5:$A$200,'Source Inventory'!$E$5:$E$200),"") | F15: =IFERROR(XLOOKUP(A15,'Source Inventory'!$A$5:$A$200,'Source Inventory'!$F$5:$F$200),"") | G15: =IFERROR(XLOOKUP(A15,'Source Inventory'!$A$5:$A$200,'Source Inventory'!$G$5:$G$200),"") | H15: E0011 | I15: Seattle | J15: In Use | K15: Working conclusion for MD-00011 (MD-MO-050011): In Use at Seattle; cost $1130. equipment_transfer_log TR-00011 posted Jun 26, 2026; inbound 2026-06-28 approval APR-00011. Source Ledger FA-000011; net book value $882.5. capital PO PO-2024-0003 supports the cost basis. hr_employee_status lists Maya Fontaine (E0011) as Active. | L15: 2026-08-05 | M15: =IFERROR(XLOOKUP(A15,'Source Inventory'!$A$5:$A$200,'Source Inventory'!$H$5:$H$200),"") | N15: 882.5 | O15: =IFERROR(XLOOKUP(A15,'Source Ledger'!$B$5:$B$200,'Source Ledger'!$A$5:$A$200),"") | P15: =IFERROR(XLOOKUP(A15,'Source Ledger'!$B$5:$B$200,'Source Ledger'!$D$5:$D$200),"") | Q15: High | S15: =IF(OR(R15="",R15=0),"No","Yes") | T15: =IFERROR(XLOOKUP(A15,'Source Ledger'!$B$5:$B$200,'Source Ledger'!$E$5:$E$200),"") | U15: =IFERROR(XLOOKUP(A15,'Source Ledger'!$B$5:$B$200,'Source Ledger'!$H$5:$H$200),"") | V15: =IFERROR(XLOOKUP(A15,'Source Ledger'!$B$5:$B$200,'Source Ledger'!$G$5:$G$200),"") | W15: =IF(OR(M15="",T15=""),"",T15-M15) | X15: =IF(V15="","No","Yes")
A16: MD-00012 | B16: =IFERROR(XLOOKUP(A16,'Source Inventory'!$A$5:$A$200,'Source Inventory'!$B$5:$B$200),"") | C16: =IFERROR(XLOOKUP(A16,'Source Inventory'!$A$5:$A$200,'Source Inventory'!$C$5:$C$200),"") | D16: =IFERROR(XLOOKUP(A16,'Source Inventory'!$A$5:$A$200,'Source Inventory'!$D$5:$D$200),"") | E16: =IFERROR(XLOOKUP(A16,'Source Inventory'!$A$5:$A$200,'Source Inventory'!$E$5:$E$200),"") | F16: =IFERROR(XLOOKUP(A16,'Source Inventory'!$A$5:$A$200,'Source Inventory'!$F$5:$F$200),"") | G16: =IFERROR(XLOOKUP(A16,'Source Inventory'!$A$5:$A$200,'Source Inventory'!$G$5:$G$200),"") | H16: E0012 | I16: Atlanta | J16: In Use | K16: Working conclusion for MD-00012 (MD-NE-050012): In Use at Atlanta; cost $6425. equipment_transfer_log TR-00012 posted Jan 30, 2026; inbound 2026-01-31 approval APR-00012. Source Ledger FA-000012; net book value $553.23. buy path for MD-00012 references PO-2024-0003. hr_employee_status lists Ryan Okonkwo (E0012) as Active. | L16: 2026-08-05 | M16: =IFERROR(XLOOKUP(A16,'Source Inventory'!$A$5:$A$200,'Source Inventory'!$H$5:$H$200),"") | N16: 553.23 | O16: =IFERROR(XLOOKUP(A16,'Source Ledger'!$B$5:$B$200,'Source Ledger'!$A$5:$A$200),"") | P16: =IFERROR(XLOOKUP(A16,'Source Ledger'!$B$5:$B$200,'Source Ledger'!$D$5:$D$200),"") | Q16: High | S16: =IF(OR(R16="",R16=0),"No","Yes") | T16: =IFERROR(XLOOKUP(A16,'Source Ledger'!$B$5:$B$200,'Source Ledger'!$E$5:$E$200),"") | U16: =IFERROR(XLOOKUP(A16,'Source Ledger'!$B$5:$B$200,'Source Ledger'!$H$5:$H$200),"") | V16: =IFERROR(XLOOKUP(A16,'Source Ledger'!$B$5:$B$200,'Source Ledger'!$G$5:$G$200),"") | W16: =IF(OR(M16="",T16=""),"",T16-M16) | X16: =IF(V16="","No","Yes")
... A20: MD-00016 | B20: =IFERROR(XLOOKUP(A20,'Source Inventory'!$A$5:$A$200,'Source Inventory'!$B$5:$B$200),"") | C20: =IFERROR(XLOOKUP(A20,'Source Inventory'!$A$5:$A$200,'Source Inventory'!$C$5:$C$200),"") | D20: =IFERROR(XLOOKUP(A20,'Source Inventory'!$A$5:$A$200,'Source Inventory'!$D$5:$D$200),"") | E20: =IFERROR(XLOOKUP(A20,'Source Inventory'!$A$5:$A$200,'Source Inventory'!$E$5:$E$200),"") | F20: =IFERROR(XLOOKUP(A20,'Source Inventory'!$A$5:$A$200,'Source Inventory'!$F$5:$F$200),"") | G20: =IFERROR(XLOOKUP(A20,'Source Inventory'!$A$5:$A$200,'Source Inventory'!$G$5:$G$200),"") | H20: E0016 | I20: New York | J20: In Use | K20: Asset MD-00016 — LG UltraFine 27MD5KL — reconciled to In Use in New York on $6290 acquisition. hr_employee_status lists Patrick Gallagher (E0016) as Active. Source Ledger FA-000016; net book value $968.69. PO-2024-0003 is the cited purchase order. equipment_transfer_log TR-00016 posted May 13, 2026; inbound 2026-05-17 approval APR-00016. | L20: 2026-08-05 | M20: =IFERROR(XLOOKUP(A20,'Source Inventory'!$A$5:$A$200,'Source Inventory'!$H$5:$H$200),"") | N20: 968.69 | O20: =IFERROR(XLOOKUP(A20,'Source Ledger'!$B$5:$B$200,'Source Ledger'!$A$5:$A$200),"") | P20: =IFERROR(XLOOKUP(A20,'Source Ledger'!$B$5:$B$200,'Source Ledger'!$D$5:$D$200),"") | Q20: High | S20: =IF(OR(R20="",R20=0),"No","Yes") | T20: =IFERROR(XLOOKUP(A20,'Source Ledger'!$B$5:$B$200,'Source Ledger'!$E$5:$E$200),"") | U20: =IFERROR(XLOOKUP(A20,'Source Ledger'!$B$5:$B$200,'Source Ledger'!$H$5:$H$200),"") | V20: =IFERROR(XLOOKUP(A20,'Source Ledger'!$B$5:$B$200,'Source Ledger'!$G$5:$G$200),"") | W20: =IF(OR(M20="",T20=""),"",T20-M20) | X20: =IF(V20="","No","Yes")
A21: MD-00017 | B21: =IFERROR(XLOOKUP(A21,'Source Inventory'!$A$5:$A$200,'Source Inventory'!$B$5:$B$200),"") | C21: =IFERROR(XLOOKUP(A21,'Source Inventory'!$A$5:$A$200,'Source Inventory'!$C$5:$C$200),"") | D21: =IFERROR(XLOOKUP(A21,'Source Inventory'!$A$5:$A$200,'Source Inventory'!$D$5:$D$200),"") | E21: =IFERROR(XLOOKUP(A21,'Source Inventory'!$A$5:$A$200,'Source Inventory'!$E$5:$E$200),"") | F21: =IFERROR(XLOOKUP(A21,'Source Inventory'!$A$5:$A$200,'Source Inventory'!$F$5:$F$200),"") | G21: =IFERROR(XLOOKUP(A21,'Source Inventory'!$A$5:$A$200,'Source Inventory'!$G$5:$G$200),"") | H21: E0017 | I21: Seattle | J21: In Use | K21: Asset MD-00017 — Samsung ViewFinity S8 — reconciled to In Use in Seattle on $1985 acquisition. hr_employee_status lists Irene Cho (E0017) as Active. Source Ledger FA-000017; net book value $0. order PO-2025-0004 appears in the purchasing extract. equipment_transfer_log TR-00017 posted Jun 17, 2026; inbound 2026-06-19 approval APR-00017. | L21: 2026-08-05 | M21: =IFERROR(XLOOKUP(A21,'Source Inventory'!$A$5:$A$200,'Source Inventory'!$H$5:$H$200),"") | N21: 0 | O21: =IFERROR(XLOOKUP(A21,'Source Ledger'!$B$5:$B$200,'Source Ledger'!$A$5:$A$200),"") | P21: =IFERROR(XLOOKUP(A21,'Source Ledger'!$B$5:$B$200,'Source Ledger'!$D$5:$D$200),"") | Q21: High | R21: EX-0001 | S21: =IF(OR(R21="",R21=0),"No","Yes") | T21: =IFERROR(XLOOKUP(A21,'Source Ledger'!$B$5:$B$200,'Source Ledger'!$E$5:$E$200),"") | U21: =IFERROR(XLOOKUP(A21,'Source Ledger'!$B$5:$B$200,'Source Ledger'!$H$5:$H$200),"") | V21: =IFERROR(XLOOKUP(A21,'Source Ledger'!$B$5:$B$200,'Source Ledger'!$G$5:$G$200),"") | W21: =IF(OR(M21="",T21=""),"",T21-M21) | X21: =IF(V21="","No","Yes")
A22: MD-00018 | B22: =IFERROR(XLOOKUP(A22,'Source Inventory'!$A$5:$A$200,'Source Inventory'!$B$5:$B$200),"") | C22: =IFERROR(XLOOKUP(A22,'Source Inventory'!$A$5:$A$200,'Source Inventory'!$C$5:$C$200),"") | D22: =IFERROR(XLOOKUP(A22,'Source Inventory'!$A$5:$A$200,'Source Inventory'!$D$5:$D$200),"") | E22: =IFERROR(XLOOKUP(A22,'Source Inventory'!$A$5:$A$200,'Source Inventory'!$E$5:$E$200),"") | F22: =IFERROR(XLOOKUP(A22,'Source Inventory'!$A$5:$A$200,'Source Inventory'!$F$5:$F$200),"") | G22: =IFERROR(XLOOKUP(A22,'Source Inventory'!$A$5:$A$200,'Source Inventory'!$G$5:$G$200),"") | H22: E0018 | I22: Atlanta | J22: In Use | K22: Asset MD-00018 — BenQ PD2705U — reconciled to In Use in Atlanta on $700 acquisition. hr_employee_status lists Theo Barnett (E0018) as Active. Source Ledger FA-000018; net book value $412.14. PO-2025-0004 is the cited purchase order. equipment_transfer_log TR-00018 posted Jan 22, 2026; inbound 2026-01-23 approval APR-00018. | L22: 2026-08-05 | M22: =IFERROR(XLOOKUP(A22,'Source Inventory'!$A$5:$A$200,'Source Inventory'!$H$5:$H$200),"") | N22: 412.14 | O22: =IFERROR(XLOOKUP(A22,'Source Ledger'!$B$5:$B$200,'Source Ledger'!$A$5:$A$200),"") | P22: =IFERROR(XLOOKUP(A22,'Source Ledger'!$B$5:$B$200,'Source Ledger'!$D$5:$D$200),"") | Q22: High | S22: =IF(OR(R22="",R22=0),"No","Yes") | T22: =IFERROR(XLOOKUP(A22,'Source Ledger'!$B$5:$B$200,'Source Ledger'!$E$5:$E$200),"") | U22: =IFERROR(XLOOKUP(A22,'Source Ledger'!$B$5:$B$200,'Source Ledger'!$H$5:$H$200),"") | V22: =IFERROR(XLOOKUP(A22,'Source Ledger'!$B$5:$B$200,'Source Ledger'!$G$5:$G$200),"") | W22: =IF(OR(M22="",T22=""),"",T22-M22) | X22: =IF(V22="","No","Yes")
A23: MD-00019 | B23: =IFERROR(XLOOKUP(A23,'Source Inventory'!$A$5:$A$200,'Source Inventory'!$B$5:$B$200),"") | C23: =IFERROR(XLOOKUP(A23,'Source Inventory'!$A$5:$A$200,'Source Inventory'!$C$5:$C$200),"") | D23: =IFERROR(XLOOKUP(A23,'Source Inventory'!$A$5:$A$200,'Source Inventory'!$D$5:$D$200),"") | E23: =IFERROR(XLOOKUP(A23,'Source Inventory'!$A$5:$A$200,'Source Inventory'!$E$5:$E$200),"") | F23: =IFERROR(XLOOKUP(A23,'Source Inventory'!$A$5:$A$200,'Source Inventory'!$F$5:$F$200),"") | G23: =IFERROR(XLOOKUP(A23,'Source Inventory'!$A$5:$A$200,'Source Inventory'!$G$5:$G$200),"") | H23: E0019 | I23: Chicago | J23: In Use | K23: Asset MD-00019 — Dell P2422H — reconciled to In Use in Chicago on $1175 acquisition. hr_employee_status lists Jasmine Reed (E0019) as Active. Source Ledger FA-000019; net book value $795.4. acquisition recorded on PO-2025-0004. equipment_transfer_log TR-00019 posted Feb 23, 2026; inbound 2026-02-26 approval APR-00019. | L23: 2026-08-05 | M23: =IFERROR(XLOOKUP(A23,'Source Inventory'!$A$5:$A$200,'Source Inventory'!$H$5:$H$200),"") | N23: 795.4 | O23: =IFERROR(XLOOKUP(A23,'Source Ledger'!$B$5:$B$200,'Source Ledger'!$A$5:$A$200),"") | P23: =IFERROR(XLOOKUP(A23,'Source Ledger'!$B$5:$B$200,'Source Ledger'!$D$5:$D$200),"") | Q23: High | S23: =IF(OR(R23="",R23=0),"No","Yes") | T23: =IFERROR(XLOOKUP(A23,'Source Ledger'!$B$5:$B$200,'Source Ledger'!$E$5:$E$200),"") | U23: =IFERROR(XLOOKUP(A23,'Source Ledger'!$B$5:$B$200,'Source Ledger'!$H$5:$H$200),"") | V23: =IFERROR(XLOOKUP(A23,'Source Ledger'!$B$5:$B$200,'Source Ledger'!$G$5:$G$200),"") | W23: =IF(OR(M23="",T23=""),"",T23-M23) | X23: =IF(V23="","No","Yes")
A24: MD-00020 | B24: =IFERROR(XLOOKUP(A24,'Source Inventory'!$A$5:$A$200,'Source Inventory'!$B$5:$B$200),"") | C24: =IFERROR(XLOOKUP(A24,'Source Inventory'!$A$5:$A$200,'Source Inventory'!$C$5:$C$200),"") | D24: =IFERROR(XLOOKUP(A24,'Source Inventory'!$A$5:$A$200,'Source Inventory'!$D$5:$D$200),"") | E24: =IFERROR(XLOOKUP(A24,'Source Inventory'!$A$5:$A$200,'Source Inventory'!$E$5:$E$200),"") | F24: =IFERROR(XLOOKUP(A24,'Source Inventory'!$A$5:$A$200,'Source Inventory'!$F$5:$F$200),"") | G24: =IFERROR(XLOOKUP(A24,'Source Inventory'!$A$5:$A$200,'Source Inventory'!$G$5:$G$200),"") | H24: E0020 | I24: Dallas | J24: In Use | K24: Asset MD-00020 — LG UltraFine 27MD5KL — reconciled to In Use in Dallas on $6470 acquisition. hr_employee_status lists Luis Navarro (E0020) as Active. equipment_transfer_log TR-00020 posted Mar 28, 2026; inbound 2026-03-30 approval APR-00020. Source Ledger FA-000020; net book value $1446.34. capital PO PO-2025-0004 supports the cost basis. | L24: 2026-08-05 | M24: =IFERROR(XLOOKUP(A24,'Source Inventory'!$A$5:$A$200,'Source Inventory'!$H$5:$H$200),"") | N24: 1446.34 | O24: =IFERROR(XLOOKUP(A24,'Source Ledger'!$B$5:$B$200,'Source Ledger'!$A$5:$A$200),"") | P24: =IFERROR(XLOOKUP(A24,'Source Ledger'!$B$5:$B$200,'Source Ledger'!$D$5:$D$200),"") | Q24: High | S24: =IF(OR(R24="",R24=0),"No","Yes") | T24: =IFERROR(XLOOKUP(A24,'Source Ledger'!$B$5:$B$200,'Source Ledger'!$E$5:$E$200),"") | U24: =IFERROR(XLOOKUP(A24,'Source Ledger'!$B$5:$B$200,'Source Ledger'!$H$5:$H$200),"") | V24: =IFERROR(XLOOKUP(A24,'Source Ledger'!$B$5:$B$200,'Source Ledger'!$G$5:$G$200),"") | W24: =IF(OR(M24="",T24=""),"",T24-M24) | X24: =IF(V24="","No","Yes")
A25: MD-00021 | B25: =IFERROR(XLOOKUP(A25,'Source Inventory'!$A$5:$A$200,'Source Inventory'!$B$5:$B$200),"") | C25: =IFERROR(XLOOKUP(A25,'Source Inventory'!$A$5:$A$200,'Source Inventory'!$C$5:$C$200),"") | D25: =IFERROR(XLOOKUP(A25,'Source Inventory'!$A$5:$A$200,'Source Inventory'!$D$5:$D$200),"") | E25: =IFERROR(XLOOKUP(A25,'Source Inventory'!$A$5:$A$200,'Source Inventory'!$E$5:$E$200),"") | F25: =IFERROR(XLOOKUP(A25,'Source Inventory'!$A$5:$A$200,'Source Inventory'!$F$5:$F$200),"") | G25: =IFERROR(XLOOKUP(A25,'Source Inventory'!$A$5:$A$200,'Source Inventory'!$G$5:$G$200),"") | H25: E0021 | I25: Denver | J25: In Use | K25: Asset MD-00021 — Samsung ViewFinity S8 — reconciled to In Use in Denver on $1850 acquisition. duplicate serial MD-LA-050021 flagged on the register. equipment_transfer_log TR-00021 posted May 02, 2026; inbound 2026-05-03 approval APR-00021. Source Ledger FA-000021; net book value $124.52. buy path for MD-00021 references PO-2022-0005. hr_employee_status lists Grace Lindholm (E0021) as Active. | L25: 2026-08-05 | M25: =IFERROR(XLOOKUP(A25,'Source Inventory'!$A$5:$A$200,'Source Inventory'!$H$5:$H$200),"") | N25: 124.52 | O25: =IFERROR(XLOOKUP(A25,'Source Ledger'!$B$5:$B$200,'Source Ledger'!$A$5:$A$200),"") | P25: =IFERROR(XLOOKUP(A25,'Source Ledger'!$B$5:$B$200,'Source Ledger'!$D$5:$D$200),"") | Q25: Medium | R25: EX-0002 | S25: =IF(OR(R25="",R25=0),"No","Yes") | T25: =IFERROR(XLOOKUP(A25,'Source Ledger'!$B$5:$B$200,'Source Ledger'!$E$5:$E$200),"") | U25: =IFERROR(XLOOKUP(A25,'Source Ledger'!$B$5:$B$200,'Source Ledger'!$H$5:$H$200),"") | V25: =IFERROR(XLOOKUP(A25,'Source Ledger'!$B$5:$B$200,'Source Ledger'!$G$5:$G$200),"") | W25: =IF(OR(M25="",T25=""),"",T25-M25) | X25: =IF(V25="","No","Yes")
A26: MD-00022 | B26: =IFERROR(XLOOKUP(A26,'Source Inventory'!$A$5:$A$200,'Source Inventory'!$B$5:$B$200),"") | C26: =IFERROR(XLOOKUP(A26,'Source Inventory'!$A$5:$A$200,'Source Inventory'!$C$5:$C$200),"") | D26: =IFERROR(XLOOKUP(A26,'Source Inventory'!$A$5:$A$200,'Source Inventory'!$D$5:$D$200),"") | E26: =IFERROR(XLOOKUP(A26,'Source Inventory'!$A$5:$A$200,'Source Inventory'!$E$5:$E$200),"") | F26: =IFERROR(XLOOKUP(A26,'Source Inventory'!$A$5:$A$200,'Source Inventory'!$F$5:$F$200),"") | G26: =IFERROR(XLOOKUP(A26,'Source Inventory'!$A$5:$A$200,'Source Inventory'!$G$5:$G$200),"") | H26: E0022 | I26: New York | J26: In Use | K26: Working conclusion for MD-00022 (MD-MO-050022): In Use at New York; cost $565. hardware_purchase_orders.csv ties MD-00022 to PO-2022-0005. hr_employee_status lists Andre Baptiste (E0022) as Active. equipment_transfer_log TR-00022 posted Jun 03, 2026; inbound 2026-06-05 approval APR-00022. Source Ledger FA-000022; net book value $371.95. | L26: 2026-08-05 | M26: =IFERROR(XLOOKUP(A26,'Source Inventory'!$A$5:$A$200,'Source Inventory'!$H$5:$H$200),"") | N26: 371.95 | O26: =IFERROR(XLOOKUP(A26,'Source Ledger'!$B$5:$B$200,'Source Ledger'!$A$5:$A$200),"") | P26: =IFERROR(XLOOKUP(A26,'Source Ledger'!$B$5:$B$200,'Source Ledger'!$D$5:$D$200),"") | Q26: High | S26: =IF(OR(R26="",R26=0),"No","Yes") | T26: =IFERROR(XLOOKUP(A26,'Source Ledger'!$B$5:$B$200,'Source Ledger'!$E$5:$E$200),"") | U26: =IFERROR(XLOOKUP(A26,'Source Ledger'!$B$5:$B$200,'Source Ledger'!$H$5:$H$200),"") | V26: =IFERROR(XLOOKUP(A26,'Source Ledger'!$B$5:$B$200,'Source Ledger'!$G$5:$G$200),"") | W26: =IF(OR(M26="",T26=""),"",T26-M26) | X26: =IF(V26="","No","Yes")
A27: MD-00023 | B27: =IFERROR(XLOOKUP(A27,'Source Inventory'!$A$5:$A$200,'Source Inventory'!$B$5:$B$200),"") | C27: =IFERROR(XLOOKUP(A27,'Source Inventory'!$A$5:$A$200,'Source Inventory'!$C$5:$C$200),"") | D27: =IFERROR(XLOOKUP(A27,'Source Inventory'!$A$5:$A$200,'Source Inventory'!$D$5:$D$200),"") | E27: =IFERROR(XLOOKUP(A27,'Source Inventory'!$A$5:$A$200,'Source Inventory'!$E$5:$E$200),"") | F27: =IFERROR(XLOOKUP(A27,'Source Inventory'!$A$5:$A$200,'Source Inventory'!$F$5:$F$200),"") | G27: =IFERROR(XLOOKUP(A27,'Source Inventory'!$A$5:$A$200,'Source Inventory'!$G$5:$G$200),"") | H27: E0023 | I27: Seattle | J27: In Use | K27: Working conclusion for MD-00023 (MD-MO-050023): In Use at Seattle; cost $1040. PO PO-2022-0005 documents the buy for MD-00023. hr_employee_status lists Nina Kowalski (E0023) as Active. equipment_transfer_log TR-00023 posted Jul 08, 2026; inbound 2026-07-09 approval APR-00023. Source Ledger FA-000023; net book value $823.6. | L27: 2026-08-05 | M27: =IFERROR(XLOOKUP(A27,'Source Inventory'!$A$5:$A$200,'Source Inventory'!$H$5:$H$200),"") | N27: 823.6 | O27: =IFERROR(XLOOKUP(A27,'Source Ledger'!$B$5:$B$200,'Source Ledger'!$A$5:$A$200),"") | P27: =IFERROR(XLOOKUP(A27,'Source Ledger'!$B$5:$B$200,'Source Ledger'!$D$5:$D$200),"") | Q27: High | S27: =IF(OR(R27="",R27=0),"No","Yes") | T27: =IFERROR(XLOOKUP(A27,'Source Ledger'!$B$5:$B$200,'Source Ledger'!$E$5:$E$200),"") | U27: =IFERROR(XLOOKUP(A27,'Source Ledger'!$B$5:$B$200,'Source Ledger'!$H$5:$H$200),"") | V27: =IFERROR(XLOOKUP(A27,'Source Ledger'!$B$5:$B$200,'Source Ledger'!$G$5:$G$200),"") | W27: =IF(OR(M27="",T27=""),"",T27-M27) | X27: =IF(V27="","No","Yes")
A28: MD-00024 | B28: =IFERROR(XLOOKUP(A28,'Source Inventory'!$A$5:$A$200,'Source Inventory'!$B$5:$B$200),"") | C28: =IFERROR(XLOOKUP(A28,'Source Inventory'!$A$5:$A$200,'Source Inventory'!$C$5:$C$200),"") | D28: =IFERROR(XLOOKUP(A28,'Source Inventory'!$A$5:$A$200,'Source Inventory'!$D$5:$D$200),"") | E28: =IFERROR(XLOOKUP(A28,'Source Inventory'!$A$5:$A$200,'Source Inventory'!$E$5:$E$200),"") | F28: =IFERROR(XLOOKUP(A28,'Source Inventory'!$A$5:$A$200,'Source Inventory'!$F$5:$F$200),"") | G28: =IFERROR(XLOOKUP(A28,'Source Inventory'!$A$5:$A$200,'Source Inventory'!$G$5:$G$200),"") | H28: E0024 | I28: Atlanta | J28: In Use | K28: Working conclusion for MD-00024 (MD-NE-050024): In Use at Atlanta; cost $6335. capital PO PO-2022-0005 supports the cost basis. hr_employee_status lists Chris Daley (E0024) as Active. equipment_transfer_log TR-00024 posted Jan 18, 2026; inbound 2026-01-21 approval APR-00024. Source Ledger FA-000024; net book value $503.85. | L28: 2026-08-05 | M28: =IFERROR(XLOOKUP(A28,'Source Inventory'!$A$5:$A$200,'Source Inventory'!$H$5:$H$200),"") | N28: 503.85 | O28: =IFERROR(XLOOKUP(A28,'Source Ledger'!$B$5:$B$200,'Source Ledger'!$A$5:$A$200),"") | P28: =IFERROR(XLOOKUP(A28,'Source Ledger'!$B$5:$B$200,'Source Ledger'!$D$5:$D$200),"") | Q28: High | S28: =IF(OR(R28="",R28=0),"No","Yes") | T28: =IFERROR(XLOOKUP(A28,'Source Ledger'!$B$5:$B$200,'Source Ledger'!$E$5:$E$200),"") | U28: =IFERROR(XLOOKUP(A28,'Source Ledger'!$B$5:$B$200,'Source Ledger'!$H$5:$H$200),"") | V28: =IFERROR(XLOOKUP(A28,'Source Ledger'!$B$5:$B$200,'Source Ledger'!$G$5:$G$200),"") | W28: =IF(OR(M28="",T28=""),"",T28-M28) | X28: =IF(V28="","No","Yes")
A29: MD-00025 | B29: =IFERROR(XLOOKUP(A29,'Source Inventory'!$A$5:$A$200,'Source Inventory'!$B$5:$B$200),"") | C29: =IFERROR(XLOOKUP(A29,'Source Inventory'!$A$5:$A$200,'Source Inventory'!$C$5:$C$200),"") | D29: =IFERROR(XLOOKUP(A29,'Source Inventory'!$A$5:$A$200,'Source Inventory'!$D$5:$D$200),"") | E29: =IFERROR(XLOOKUP(A29,'Source Inventory'!$A$5:$A$200,'Source Inventory'!$E$5:$E$200),"") | F29: =IFERROR(XLOOKUP(A29,'Source Inventory'!$A$5:$A$200,'Source Inventory'!$F$5:$F$200),"") | G29: =IFERROR(XLOOKUP(A29,'Source Inventory'!$A$5:$A$200,'Source Inventory'!$G$5:$G$200),"") | H29: E0025 | I29: Chicago | J29: In Use | K29: Working conclusion for MD-00025 (MD-LA-050021): In Use at Chicago; cost $2030. buy path for MD-00025 references PO-2022-0005. hr_employee_status lists Fatima Hussein (E0025) as Active. duplicate serial MD-LA-050021 flagged on the register. Source Ledger FA-000025; net book value $0. equipment_transfer_log TR-00025 posted Jan 21, 2026; inbound 2026-01-22 approval APR-00025. | L29: 2026-08-05 | M29: =IFERROR(XLOOKUP(A29,'Source Inventory'!$A$5:$A$200,'Source Inventory'!$H$5:$H$200),"") | N29: 0 | O29: =IFERROR(XLOOKUP(A29,'Source Ledger'!$B$5:$B$200,'Source Ledger'!$A$5:$A$200),"") | P29: =IFERROR(XLOOKUP(A29,'Source Ledger'!$B$5:$B$200,'Source Ledger'!$D$5:$D$200),"") | Q29: Medium | R29: EX-0003, EX-0004 | S29: =IF(OR(R29="",R29=0),"No","Yes") | T29: =IFERROR(XLOOKUP(A29,'Source Ledger'!$B$5:$B$200,'Source Ledger'!$E$5:$E$200),"") | U29: =IFERROR(XLOOKUP(A29,'Source Ledger'!$B$5:$B$200,'Source Ledger'!$H$5:$H$200),"") | V29: =IFERROR(XLOOKUP(A29,'Source Ledger'!$B$5:$B$200,'Source Ledger'!$G$5:$G$200),"") | W29: =IF(OR(M29="",T29=""),"",T29-M29) | X29: =IF(V29="","No","Yes")
A30: MD-00026 | B30: =IFERROR(XLOOKUP(A30,'Source Inventory'!$A$5:$A$200,'Source Inventory'!$B$5:$B$200),"") | C30: =IFERROR(XLOOKUP(A30,'Source Inventory'!$A$5:$A$200,'Source Inventory'!$C$5:$C$200),"") | D30: =IFERROR(XLOOKUP(A30,'Source Inventory'!$A$5:$A$200,'Source Inventory'!$D$5:$D$200),"") | E30: =IFERROR(XLOOKUP(A30,'Source Inventory'!$A$5:$A$200,'Source Inventory'!$E$5:$E$200),"") | F30: =IFERROR(XLOOKUP(A30,'Source Inventory'!$A$5:$A$200,'Source Inventory'!$F$5:$F$200),"") | G30: =IFERROR(XLOOKUP(A30,'Source Inventory'!$A$5:$A$200,'Source Inventory'!$G$5:$G$200),"") | H30: E0026 | I30: Dallas | J30: In Use | K30: Working conclusion for MD-00026 (MD-MO-050026): In Use at Dallas; cost $745. acquisition recorded on PO-2022-0005. hr_employee_status lists Brendan Walsh (E0026) as Active. equipment_transfer_log TR-00026 posted Feb 23, 2026; inbound 2026-02-27 approval APR-00026. Source Ledger FA-000026; net book value $382.34. | L30: 2026-08-05 | M30: =IFERROR(XLOOKUP(A30,'Source Inventory'!$A$5:$A$200,'Source Inventory'!$H$5:$H$200),"") | N30: 382.34 | O30: =IFERROR(XLOOKUP(A30,'Source Ledger'!$B$5:$B$200,'Source Ledger'!$A$5:$A$200),"") | P30: =IFERROR(XLOOKUP(A30,'Source Ledger'!$B$5:$B$200,'Source Ledger'!$D$5:$D$200),"") | Q30: High | R30: EX-0005 | S30: =IF(OR(R30="",R30=0),"No","Yes") | T30: =IFERROR(XLOOKUP(A30,'Source Ledger'!$B$5:$B$200,'Source Ledger'!$E$5:$E$200),"") | U30: =IFERROR(XLOOKUP(A30,'Source Ledger'!$B$5:$B$200,'Source Ledger'!$H$5:$H$200),"") | V30: =IFERROR(XLOOKUP(A30,'Source Ledger'!$B$5:$B$200,'Source Ledger'!$G$5:$G$200),"") | W30: =IF(OR(M30="",T30=""),"",T30-M30) | X30: =IF(V30="","No","Yes")
A31: MD-00027 | B31: =IFERROR(XLOOKUP(A31,'Source Inventory'!$A$5:$A$200,'Source Inventory'!$B$5:$B$200),"") | C31: =IFERROR(XLOOKUP(A31,'Source Inventory'!$A$5:$A$200,'Source Inventory'!$C$5:$C$200),"") | D31: =IFERROR(XLOOKUP(A31,'Source Inventory'!$A$5:$A$200,'Source Inventory'!$D$5:$D$200),"") | E31: =IFERROR(XLOOKUP(A31,'Source Inventory'!$A$5:$A$200,'Source Inventory'!$E$5:$E$200),"") | F31: =IFERROR(XLOOKUP(A31,'Source Inventory'!$A$5:$A$200,'Source Inventory'!$F$5:$F$200),"") | G31: =IFERROR(XLOOKUP(A31,'Source Inventory'!$A$5:$A$200,'Source Inventory'!$G$5:$G$200),"") | H31: E0027 | I31: Denver | J31: In Use | K31: Asset MD-00027 — BenQ PD2705U — reconciled to In Use in Denver on $1220 acquisition. hr_employee_status lists Yuki Tanaka (E0027) as Active. equipment_transfer_log TR-00027 posted Mar 31, 2026; inbound 2026-04-06 approval APR-00027. Source Ledger FA-000027; net book value $672.21. purchasing file shows PO-2022-0005 for this unit. | L31: 2026-08-05 | M31: =IFERROR(XLOOKUP(A31,'Source Inventory'!$A$5:$A$200,'Source Inventory'!$H$5:$H$200),"") | N31: 672.21 | O31: =IFERROR(XLOOKUP(A31,'Source Ledger'!$B$5:$B$200,'Source Ledger'!$A$5:$A$200),"") | P31: =IFERROR(XLOOKUP(A31,'Source Ledger'!$B$5:$B$200,'Source Ledger'!$D$5:$D$200),"") | Q31: High | R31: EX-0006 | S31: =IF(OR(R31="",R31=0),"No","Yes") | T31: =IFERROR(XLOOKUP(A31,'Source Ledger'!$B$5:$B$200,'Source Ledger'!$E$5:$E$200),"") | U31: =IFERROR(XLOOKUP(A31,'Source Ledger'!$B$5:$B$200,'Source Ledger'!$H$5:$H$200),"") | V31: =IFERROR(XLOOKUP(A31,'Source Ledger'!$B$5:$B$200,'Source Ledger'!$G$5:$G$200),"") | W31: =IF(OR(M31="",T31=""),"",T31-M31) | X31: =IF(V31="","No","Yes")
A32: MD-00028 | B32: =IFERROR(XLOOKUP(A32,'Source Inventory'!$A$5:$A$200,'Source Inventory'!$B$5:$B$200),"") | C32: =IFERROR(XLOOKUP(A32,'Source Inventory'!$A$5:$A$200,'Source Inventory'!$C$5:$C$200),"") | D32: =IFERROR(XLOOKUP(A32,'Source Inventory'!$A$5:$A$200,'Source Inventory'!$D$5:$D$200),"") | E32: =IFERROR(XLOOKUP(A32,'Source Inventory'!$A$5:$A$200,'Source Inventory'!$E$5:$E$200),"") | F32: =IFERROR(XLOOKUP(A32,'Source Inventory'!$A$5:$A$200,'Source Inventory'!$F$5:$F$200),"") | G32: =IFERROR(XLOOKUP(A32,'Source Inventory'!$A$5:$A$200,'Source Inventory'!$G$5:$G$200),"") | H32: E0028 | I32: New York | J32: In Use | K32: Asset MD-00028 — Dell P2422H — reconciled to In Use in New York on $6200 acquisition. hr_employee_status lists Megan Copeland (E0028) as Active. equipment_transfer_log TR-00028 posted May 01, 2026; inbound 2026-05-02 approval APR-00028. Source Ledger FA-000028; net book value $914.09. acquisition recorded on PO-2023-0006. | L32: 2026-08-05 | M32: =IFERROR(XLOOKUP(A32,'Source Inventory'!$A$5:$A$200,'Source Inventory'!$H$5:$H$200),"") | N32: 914.09 | O32: =IFERROR(XLOOKUP(A32,'Source Ledger'!$B$5:$B$200,'Source Ledger'!$A$5:$A$200),"") | P32: =IFERROR(XLOOKUP(A32,'Source Ledger'!$B$5:$B$200,'Source Ledger'!$D$5:$D$200),"") | Q32: High | R32: EX-0007 | S32: =IF(OR(R32="",R32=0),"No","Yes") | T32: =IFERROR(XLOOKUP(A32,'Source Ledger'!$B$5:$B$200,'Source Ledger'!$E$5:$E$200),"") | U32: =IFERROR(XLOOKUP(A32,'Source Ledger'!$B$5:$B$200,'Source Ledger'!$H$5:$H$200),"") | V32: =IFERROR(XLOOKUP(A32,'Source Ledger'!$B$5:$B$200,'Source Ledger'!$G$5:$G$200),"") | W32: =IF(OR(M32="",T32=""),"",T32-M32) | X32: =IF(V32="","No","Yes")
A33: MD-00029 | B33: =IFERROR(XLOOKUP(A33,'Source Inventory'!$A$5:$A$200,'Source Inventory'!$B$5:$B$200),"") | C33: =IFERROR(XLOOKUP(A33,'Source Inventory'!$A$5:$A$200,'Source Inventory'!$C$5:$C$200),"") | D33: =IFERROR(XLOOKUP(A33,'Source Inventory'!$A$5:$A$200,'Source Inventory'!$D$5:$D$200),"") | E33: =IFERROR(XLOOKUP(A33,'Source Inventory'!$A$5:$A$200,'Source Inventory'!$E$5:$E$200),"") | F33: =IFERROR(XLOOKUP(A33,'Source Inventory'!$A$5:$A$200,'Source Inventory'!$F$5:$F$200),"") | G33: =IFERROR(XLOOKUP(A33,'Source Inventory'!$A$5:$A$200,'Source Inventory'!$G$5:$G$200),"") | H33: E0029 | I33: Seattle | J33: In Use | K33: Asset MD-00029 — Dell U2723QE — reconciled to In Use in Seattle on $1895 acquisition. hr_employee_status lists Omar Haddad (E0029) as Active. equipment_transfer_log TR-00029 posted Jun 05, 2026; inbound 2026-06-11 approval APR-00029. Source Ledger FA-000029; net book value $0. purchasing file shows PO-2023-0006 for this unit. | L33: 2026-08-05 | M33: =IFERROR(XLOOKUP(A33,'Source Inventory'!$A$5:$A$200,'Source Inventory'!$H$5:$H$200),"") | N33: 0 | O33: =IFERROR(XLOOKUP(A33,'Source Ledger'!$B$5:$B$200,'Source Ledger'!$A$5:$A$200),"") | P33: =IFERROR(XLOOKUP(A33,'Source Ledger'!$B$5:$B$200,'Source Ledger'!$D$5:$D$200),"") | Q33: High | R33: EX-0008 | S33: =IF(OR(R33="",R33=0),"No","Yes") | T33: =IFERROR(XLOOKUP(A33,'Source Ledger'!$B$5:$B$200,'Source Ledger'!$E$5:$E$200),"") | U33: =IFERROR(XLOOKUP(A33,'Source Ledger'!$B$5:$B$200,'Source Ledger'!$H$5:$H$200),"") | V33: =IFERROR(XLOOKUP(A33,'Source Ledger'!$B$5:$B$200,'Source Ledger'!$G$5:$G$200),"") | W33: =IF(OR(M33="",T33=""),"",T33-M33) | X33: =IF(V33="","No","Yes")
A34: MD-00030 | B34: =IFERROR(XLOOKUP(A34,'Source Inventory'!$A$5:$A$200,'Source Inventory'!$B$5:$B$200),"") | C34: =IFERROR(XLOOKUP(A34,'Source Inventory'!$A$5:$A$200,'Source Inventory'!$C$5:$C$200),"") | D34: =IFERROR(XLOOKUP(A34,'Source Inventory'!$A$5:$A$200,'Source Inventory'!$D$5:$D$200),"") | E34: =IFERROR(XLOOKUP(A34,'Source Inventory'!$A$5:$A$200,'Source Inventory'!$E$5:$E$200),"") | F34: =IFERROR(XLOOKUP(A34,'Source Inventory'!$A$5:$A$200,'Source Inventory'!$F$5:$F$200),"") | G34: =IFERROR(XLOOKUP(A34,'Source Inventory'!$A$5:$A$200,'Source Inventory'!$G$5:$G$200),"") | H34: E0030 | I34: Atlanta | J34: In Use | K34: Files reviewed for MD-00030: Samsung ViewFinity S8, basis $610, operating site Atlanta, status In Use. equipment_transfer_log TR-00030 posted Jan 10, 2026; inbound 2026-01-13 approval APR-00030. buy path for MD-00030 references PO-2023-0006. Source Ledger FA-000030; net book value $355.14. hr_employee_status lists Stephanie Ruiz (E0030) as Active. | L34: 2026-08-05 | M34: =IFERROR(XLOOKUP(A34,'Source Inventory'!$A$5:$A$200,'Source Inventory'!$H$5:$H$200),"") | N34: 355.14 | O34: =IFERROR(XLOOKUP(A34,'Source Ledger'!$B$5:$B$200,'Source Ledger'!$A$5:$A$200),"") | P34: =IFERROR(XLOOKUP(A34,'Source Ledger'!$B$5:$B$200,'Source Ledger'!$D$5:$D$200),"") | Q34: High | R34: EX-0009 | S34: =IF(OR(R34="",R34=0),"No","Yes") | T34: =IFERROR(XLOOKUP(A34,'Source Ledger'!$B$5:$B$200,'Source Ledger'!$E$5:$E$200),"") | U34: =IFERROR(XLOOKUP(A34,'Source Ledger'!$B$5:$B$200,'Source Ledger'!$H$5:$H$200),"") | V34: =IFERROR(XLOOKUP(A34,'Source Ledger'!$B$5:$B$200,'Source Ledger'!$G$5:$G$200),"") | W34: =IF(OR(M34="",T34=""),"",T34-M34) | X34: =IF(V34="","No","Yes")
